Workbook
Name Activity: [47]LISTs!$B$2:$B$19
Name ahdeahteahg: '[48]MARS Report'!#REF!
Name aheahtaht: '[48]MARS Report'!#REF!
Name ahtdznghts: #REF!
Name ahtdznghts: #REF!
Name ahtdznghts: #REF!
Name AMC: '[49]FAS 157 Package'!$Q$4:$Q$158
Name Andon: #REF!
Name Andon: #REF!
Name Andon: #REF!
Name APPENDIX: #REF!
Name bus: '[48]MARS Report'!#REF!
Name bus: '[48]MARS Report'!#REF!
Name bus: '[48]MARS Report'!#REF!
Name CHARTS: [27]A!$DX$1:$HB$289
Name CLIN: '[61]Drop Downs'!$B$2:$B$11
Name ColorFunction__G_1_I4_V4__14_100: #REF!
Name ColorFunction__G_1_I4_V4__14_100: #REF!
Name ColorFunction__G_1_I4_V4__14_100: #REF!
Name DATA: [27]A!$A$1:$U$153
Name Data1231: #REF!
Name Data1231: #REF!
Name Data1231: #REF!
Name Data930: #REF!
Name Data930: #REF!
Name Data930: #REF!
Name dd: #REF!
Name dd: #REF!
Name display: [62]values!$D$3:$D$14
Name DisplayInDropDown: '[48]MARS Report'!#REF!
Name DisplayinValue: '[48]MARS Report'!#REF!
Name dmnfgh: #REF!
Name dmnfgh: #REF!
Name dmnfgh: #REF!
Name Done: #REF!
Name Done: #REF!
Name Done: #REF!
Name eahtzdgb: #REF!
Name eahtzdgb: #REF!
Name eahtzdgb: #REF!
Name EFV: '[49]FAS 157 Package'!$N$4:$N$158
Name ejtgdb: '[48]MARS Report'!#REF!
Name End: '[48]MARS Report'!#REF!
Name End: '[48]MARS Report'!#REF!
Name End: '[48]MARS Report'!#REF!
Name END_DATE: #REF!
Name END_DATE: #REF!
Name END_DATE: #REF!
Name Entity: '[48]MARS Report'!#REF!
Name EventEndDate: [65]Border!$D$7
Name EventStartDate: [65]Border!$B$7
Name Excel_BuiltIn__FilterDatabase_4: #REF!
Name fgb: '[48]MARS Report'!#REF!
Name fgnbc: #REF!
Name fhbnv: #REF!
Name fhbnv: #REF!
Name fhbnv: #REF!
Name fhdvbcgh: #REF!
Name fhdvbcgh: #REF!
Name fhdvbcgh: #REF!

Sheet Agenda
A1: Typical Kaizen Event Agenda (ideally face-to-face; can also be done virtually) | D1: RETURN TO USER GUIDE
A2: Adjust this to meet the specific needs of your event. Standard elements of training, daily leader's meetings, execution of actions/changes for Monday, and report out should ALWAYS be included.
A4: USA EST | B4: Day 1 Monday | C4: Day 2 Tuesday | D4: Day 3 Wednesday | E4: Day 4 Thursday | F4: Day 5 Friday
B5: Introductions, Training, Current State | C5: Analyze Current State, Create Future State, Develop Action Plan | D5: Build, Test, Refine Solutions | E5: Implement Solutions Plan to Operationalize & Sustain Lessons Learned | F5: Present Results & Celebrate
A6: 0.33333333 | B6: Kickoff, Introductions & Safety | C6: Recap & Plan for the Day Complete Safety & Ergo Assessments | D6: Recap & Plan for the Day Complete Safety & Ergo Assessments | E6: Recap & Plan for the Day Complete Safety & Ergo Assessments | F6: Recap & Plan for the Day Complete Safety & Ergo Assessments
A7: =A6+(TIME(0,30,0)) -> 0.35416667 | B7: Lean Training: Creating a Standard | C7: Lean Training | D7: Execute Action Plan Build, Test, Refine Solutions | E7: Execute Action Plan Implement Final Solution | F7: Participant Survey Final Presentation Prep
A8: =A7+(TIME(0,30,0)) -> 0.375
A9: =A8+(TIME(0,30,0)) -> 0.39583333
A10: =A9+(TIME(0,30,0)) -> 0.41666667
A11: =A10+(TIME(0,30,0)) -> 0.4375 | C11: Analyze Current State Waste & Problem Identification Root Cause Determination Solution Generation Prioritization
A12: =A11+(TIME(0,30,0)) -> 0.45833333 | F12: Report Out
A13: =A12+(TIME(0,30,0)) -> 0.47916667 | F13: Kaizen Self Assessment
A14: =A13+(TIME(0,30,0)) -> 0.5 | B14: Lunch | C14: Lunch | D14: Lunch | E14: Lunch
A15: =A14+(TIME(0,30,0)) -> 0.52083333
A16: =A15+(TIME(0,30,0)) -> 0.54166667 | B16: Current State- Continue Reason Matrix: What has been tried | C16: Future State Creation Develop Action Plan... What changes for Monday? | D16: Execute Action Plan Build, Test, Refine Solutions | E16: Plan to Operationalize & Sustain Post-Kaizen Action Plan Lessons Learned Team Picture
A17: =A16+(TIME(0,30,0)) -> 0.5625
A18: =A17+(TIME(0,30,0)) -> 0.58333333
A19: =A18+(TIME(0,30,0)) -> 0.60416667
A20: =A19+(TIME(0,30,0)) -> 0.625
A21: =A20+(TIME(0,30,0)) -> 0.64583333
A22: =A21+(TIME(0,30,0)) -> 0.66666667 | B22: Daily Debrief (Optional) | C22: Daily Debrief (Optional) | D22: Daily Debrief (Optional)
A23: =A22+(TIME(0,30,0)) -> 0.6875 | B23: Daily Leaders Meeting | C23: Daily Leaders Meeting | D23: Daily Leaders Meeting | E23: Daily Leaders Meeting
A24: =A23+(TIME(0,30,0)) -> 0.70833333

Sheet Daily Targets
A1: Daily Target Sheet | B1: RETURN TO USER GUIDE
A2: Lists the metrics that are targeted to be impacted during the event and is updated daily and changes are being made.
A4: SQDC | B4: Business Metric | C4: Unit of Measure | D4: Baseline | E4: Target | F4: Day 1 Result | G4: Day 2 Result | H4: Day 3 Result | I4: Day 4 Result | J4: Final Result | K4: % Improved from start
A5: =#REF! -> #REF! | D5: =#REF! -> #REF! | E5: =#REF! -> #REF!
A6: =#REF! -> #REF! | D6: =#REF! -> #REF! | E6: =#REF! -> #REF!
A7: =#REF! -> #REF! | D7: =#REF! -> #REF! | E7: =#REF! -> #REF!
A8: =#REF! -> #REF! | D8: =#REF! -> #REF! | E8: =#REF! -> #REF!
A9: =#REF! -> #REF! | D9: =#REF! -> #REF! | E9: =#REF! -> #REF!
A11: Reference: Kaizen Impact Standard Target Sheet
A12: This a reference library of metrics that are typically good leading indicators for impact across SQDC + Cash and can be used to aid when selecting the target metrics for your Kaizen.
A13: SQDC+Cash | B13: Business Metrics | C13: Unit of Measure | D13: Definition | H13: Examples
A14: Safety | B14: Safety improvement | C14: Count (#) | D14: Number of improvements made to the safety of process. | H14: - Trip hazard eliminated in a manufacturing cell or office environment - Ergonomics improvement in an office environment - Cyber security risk reduction - Work/life balance and mental health improvement
B15: Compliance risk reduction | C15: Count (#) | D15: Number of compliance risks reduced in the process.This may be related to violations against internal GE policies or regulatory requirements. | H15: - Violations against company policy for Environment, Health, and Safety (EHS) violations - Occupational Safety and Health Administration (OSHA) violations - Number of data compliance violations (e.g. HIPAA, GDPR)
A16: Quality | B16: Scrap reduction | C16: Dollar ($) | D16: Scrap is the dollar value of unusable material that is left over after a product has been manufactured. | H16: - Scrap due to material non-conformances where the part cannot be repaired - Scrap due to engineering part obsolescence
B17: Defect reduction | C17: Count (#) | D17: A defect is a process non-conformance that impacts the quality of a final product. That product can be physical or transactional. May be measured in terms of "defects per million" or number of quality improvements for a process. | H17: - Number of manufacturing defects (i.e. part tolerances over allowable limit) - Number of misclassifications for field quality cases - Number of late manual journal entries (MJE) - Number of technology outages or incidents (ServiceNow)
B18: First pass yield improvement | C18: Percentage (%) | D18: First pass yield (FPY) is defined as the number of units coming out of a process divided by the number of units going into that process over a specified period of time. This metric measures the % improvement of FPY. | H18: - FPY of the tact weld operation in a manufacturing plant - FPY of the material review for the Board of Directors presentation - FPY of internal deliverables within a transactional environment (reports, QMI submissions, quarter end items, etc.)
A19: Delivery | B19: Volume output | C19: Pieces/day | D19: Volume output, on a piece part basis, is the total number of pieces / units produced over a set period of time. This metric will be reported on a daily basis.
B20: Volume output (revenue) | C20: Dollar ($) | D20: Volume output, on a revenue basis, is the $ amount (revenue generating) of the total number of pieces / units produced over a set period of time.
B21: Lead-time reduction | C21: Count (# Days) | D21: Lead time is measured from the customer perspective and is defined as the time from when the customer makes a request to the time when they receive something. This metric measures the number of lead time days reduced in a value stream. | H21: - Lead time to deliver a gas turbine to the customer - Lead time from when a purchase order is placed to when the material arrives - Lead time for finance monthly close - Lead time for a wing-to-wing Sales, Inventory & Operations Planning cycle
B22: Stockout reduction | C22: Count (# Stockouts) | D22: A stockout is an event that causes inventory to be exhausted. It occurs when customer demand for a product exceeds the amount of inventory kept on-hand. This metric measures the reduction in stockouts of a process / operation.
A23: Delivery (or Cost) | B23: Cycle time (or labor hour) reduction | C23: # of Hours | D23: Cycle time is measured from the internal process perspective, and is the hours or labor hours reduced within a process step - including value add time and non-value added time. Especially relevant for transactional process that may not be repeatable to show productivity gains. | H23: - Number of hours required for heat treatment manufacturing operation - Number of hours to develop request-for-quotation or complete supplier onboarding - Number of hours for FP&A activity (monthly estimate consolidation, forecasting, or other pacing activities) - Number of Service Level Agreement (SLA) hours
A24: Cost | B24: Space reduction | C24: Square foot (sq.ft.) | D24: The amount of space required to house a process / operation.
B25: Distance traveled | C25: Feet (ft.) | D25: The amount of physical distance traveled by an operator to perform a process / operation..
B26: Productivity (units/human hours) | C26: Percentage (%) | D26: Productivity measures the efficiency of production as an output per unit of input. This metric measures productivity of units produced compared to human hours applied.
A27: Cash | B27: Working capital improvement | C27: Dollar ($) | D27: Improvements resulting in positive cash flow impact on working capital, or operating liquidity. This metric will be reported at the net working capital improvement level, but include the following sub-areas: inventory reduction, accounts receivable reduction, accounts payable improvement | H27: - Reduction in Inventory - Reduction in Account Receivables (AR) - Increase in Account Payables (AP) - Increase in Progress Collections

Sheet Trystorming
A1: Daily Trystorm Tracking | D1: RETURN TO USER GUIDE
A2: A tool to encourage and track Trystorming throughout the event to achieve the Kaizen objectives
F4: % Complete
A5: # | B5: Gap to be Addressed | C5: Solution to Try | D5: Experiment | E5: Anticipated Result | F5: 25% | G5: 50% | H5: 75% | I5: 100% | J5: Actual Result | K5: Follow Up Actions
A6: 1
A7: 2
A8: 3
A9: 4
A10: 5
A11: 6
A12: 7
A13: 8
A14: 9
A15: 10

Sheet Daily Summary
B1: Daily Leader's Meeting 4-Block | C1: RETURN TO USER GUIDE
B2: Assesses progress at the end of each day, specifically identifying any immediate actions required to continue making progress towards the Kaizen objective. On Friday, capture the team's overall lessons learned to incorporate into the final event report out.
B4: Monday | E4: Tuesday
B5: Done Today | C5: Tomorrow's Tasks | E5: Done Today | F5: Tomorrow's Tasks
B20: Lessons Learned / Ah Ha Moments | C20: Concerns / Changes / Help Needed | E20: Lessons Learned / Ah Ha Moments | F20: Concerns / Changes / Help Needed
B36: Wednesday | E36: Thursday
B37: Done Today | C37: Tomorrow's Tasks | E37: Done Today | F37: Tomorrow's Tasks
B52: Lessons Learned / Ah Ha Moments | C52: Concerns / Changes / Help Needed | E52: Lessons Learned / Ah Ha Moments | F52: Concerns / Changes / Help Needed
B68: Friday
B69: Lessons Learned - Process/Business/Organization | C69: Lessons Learned - Lean Tools/Methodology/Culture

Sheet Kaizen Newspaper
A1: Post-Kaizen Action Plan / Kaizen Newspaper | D1: RETURN TO USER GUIDE
A2: Lists any remaining actions to be completed, which should all have a due date within 30 days of event end.
D4: Planned Date
A5: Action Step | B5: Owner | C5: Assist | E5: K+1 | F5: K+2 | G5: K+3 | H5: K+4 | I5: Comments
A6: Item 1 | B6: Jane | C6: Joe | D6: Feb 5 | E6: X
A7: Item 2 | B7: Bruce | C7: Cindy | D7: Feb 5 Feb 12 | F7: X
A8: Item 3 | B8: Jane | C8: Cindy | D8: Feb 11 | E8: X
A9: Item 4 | B9: Jane | C9: Sam | D9: Feb 5 Feb 20 | F9: X | G9: X
A10: Item 5 | B10: Cindy | C10: John | D10: Feb 20
A11: Item 6 | B11: Jane | C11: Sam | D11: Feb 22
A12: QMS - Have all Procedures, Work Instructions or Guidance documents associated with the process been identified, reviewed and updated to match the post-kaizen condition? | B12: Jane | C12: Sam | D12: Feb 22
A13: QMS - Have changes to Procedures, Work Instructions or Guidance documents been communicated and where applicable training given. | B13: Jane | C13: Sam | D13: Feb 22

Sheet Post-Kaizen Daily Mgt
B1: Post-Kaizen Daily Management | AN1: RETURN TO USER GUIDE
B2: This 8-Block Board should be built on Day 4 or 5 of the Kaizen Event and is used for 90 days following the event, with the Genba team, to ensure sustainment of the changes from your Kaizen. Ideally, this board is implemented (printed and hand written) physically, at Genba, and the team huddles daily (or at the cadence at which the process runs).
B4: Problem Statement | AN4: Run Chart
C5: This updates from the Charter tab in this Playbook. | AO5: Metric (Unit of Measure) | AP5: Scale -->
C6: =#REF! -> #REF!
AQ17: 100
AQ18: 95
AQ19: 90
AQ20: 85
AQ21: 80
AQ22: 75
AQ23: 70
AQ24: 65
AQ25: 60
AQ26: 55
AQ27: 50
AQ28: 45
... AQ36: 5
AQ37: Day --> | AR37: 1 | AS37: 2 | AT37: 3 | AU37: 4 | AV37: 5 | AW37: 6 | AX37: 7 | AY37: 8 | AZ37: 9 | BA37: 10 | BB37: 11 | BC37: 12 | BD37: 13 | BE37: 14 | BF37: 15 | BG37: 16 | BH37: 17 | BI37: 18 | BJ37: 19 | BK37: 20 | BL37: 21 | BM37: 22 | BN37: 23 | BO37: 24 | BP37: 25 | BQ37: 26 | BR37: 27 | BS37: 28 | BT37: 29 | BU37: 30 | BV37: 31
B40: Metrics | AN40: Issue Pareto
C41: The first 7 columns of this table updates from the Daily Target Sheet tab in this Playbook.
AO42: Frequency of Occurrence (Date of Occurrence) | AP42: 20
AP43: 19
AP44: 18
AP45: 17
AP46: 16
C47: ='Daily Targets'!A4 -> SQDC | E47: ='Daily Targets'!B4 -> Business Metric | I47: ='Daily Targets'!C4 -> Unit of Measure | M47: ='Daily Targets'!D4 -> Baseline | P47: ='Daily Targets'!E4 -> Target | S47: Kaizen Result | V47: ='Daily Targets'!K4 -> % Improved from start | Y47: 30 Day Result | AB47: 60 Day Result | AE47: 90 Day Result | AH47: ='Daily Targets'!K4 -> % Improved from start | AP47: 15
AP48: 14
C49: ='Daily Targets'!A5 -> #REF! | E49: ='Daily Targets'!B5 -> 0 | I49: ='Daily Targets'!C5 -> 0 | M49: ='Daily Targets'!D5 -> #REF! | P49: ='Daily Targets'!E5 -> #REF! | S49: ='Daily Targets'!J5 -> 0 | V49: ='Daily Targets'!K5 -> 0 | AP49: 13
C50: ='Daily Targets'!A6 -> #REF! | E50: ='Daily Targets'!B6 -> 0 | I50: ='Daily Targets'!C6 -> 0 | M50: ='Daily Targets'!D6 -> #REF! | P50: ='Daily Targets'!E6 -> #REF! | S50: ='Daily Targets'!J6 -> 0 | V50: ='Daily Targets'!K6 -> 0 | AP50: 12
C51: ='Daily Targets'!A7 -> #REF! | E51: ='Daily Targets'!B7 -> 0 | I51: ='Daily Targets'!C7 -> 0 | M51: ='Daily Targets'!D7 -> #REF! | P51: ='Daily Targets'!E7 -> #REF! | S51: ='Daily Targets'!J7 -> 0 | V51: ='Daily Targets'!K7 -> 0 | AP51: 11
C52: ='Daily Targets'!A8 -> #REF! | E52: ='Daily Targets'!B8 -> 0 | I52: ='Daily Targets'!C8 -> 0 | M52: ='Daily Targets'!D8 -> #REF! | P52: ='Daily Targets'!E8 -> #REF! | S52: ='Daily Targets'!J8 -> 0 | V52: ='Daily Targets'!K8 -> 0 | AP52: 10
C53: ='Daily Targets'!A9 -> #REF! | E53: ='Daily Targets'!B9 -> 0 | I53: ='Daily Targets'!C9 -> 0 | M53: ='Daily Targets'!D9 -> #REF! | P53: ='Daily Targets'!E9 -> #REF! | S53: ='Daily Targets'!J9 -> 0 | V53: ='Daily Targets'!K9 -> 0 | AP53: 9
AP54: 8
AP55: 7
AP56: 6
AP57: 5
AP58: 4 | AS58: 44625
AP59: 3 | AS59: 44625
AP60: 2 | AS60: 44624
...

Sheet Certificate
B1: Certificate of Participation | L1: RETURN TO USER GUIDE
B2: Optionally presented to each Kaizen team member, individually by the Executive Sponsor of the Kaizen Event, often along with a group photo or other nominal gift in appreciation of their participation.
D28: PLEASE CONTINUE TO PRACTICE KAIZEN, CONTINUOUSLY

Sheet Report Out
J1: RETURN TO USER GUIDE

Sheet Closure
F1: RETURN TO USER GUIDE
A2: KAIZEN | B2: =IF(#REF!="","",#REF!) -> #REF! | F2: Run Kaizen Event
A4: Kaizen | B4: Due | C4: Date | D4: Accountable | E4: Roles | F4: Task
A5: Timing | B5: Date | C5: Completed | D5: Role | E5: Engaged
A6: During kaizen | B6: =$B$2 -> #REF! | D6: PO | E6: PO, TL | F6: Standard work is completed, posted and implemented
B7: =$B$2 -> #REF! | D7: PO | E7: PO, TL | F7: Communication plan is developed and shared
B8: =$B$2 -> #REF! | D8: PO | E8: PO, TL | F8: Training plan created
B9: =$B$2 -> #REF! | D9: PO | E9: PO, TL | F9: Post-Kaizen Action Plan (newspaper) complete and all items due within 30 days
B10: =$B$2 -> #REF! | D10: PO | E10: PO, TL | F10: Visual management established and operational
B11: =$B$2 -> #REF! | D11: PO | E11: PO, TL | F11: Target state met
B12: =$B$2 -> #REF! | D12: PO | E12: PO, TL | F12: Weekly meeting for next 3 weeks scheduled with PO
B13: =$B$2 -> #REF! | D13: PO | E13: PO, TL | F13: Participant survey completed (optional)
B14: =$B$2 -> #REF! | D14: PO | E14: ES, PO, F | F14: 30/60/90 Schedule sustainment calls after 30 days, 60 days, 90 days
B15: =$B$2 -> #REF! | D15: PO | E15: ES, PO, F | F15: Key Roles Assessment completed
A16: +1 week | B16: =IF(B$2="","",$B$2+7) -> #REF! | D16: PO | E16: PO | F16: Post-Kaizen Action Plan, Communication Plan, Training Plan Status
B17: =IF(B$2="","",$B$2+7) -> #REF! | D17: PO | E17: PO | F17: Validate performance against target state
B18: =IF(B$2="","",$B$2+7) -> #REF! | D18: PO | E18: PO, ES, F | F18: Escalate to ES and F, if red
B19: =IF(B$2="","",$B$2+7) -> #REF! | D19: PO | E19: PO, TL | F19: QMS checks - Have all Procedures, Work Instructions or Guidance documents associated to the process been identified and reviewed. (Please List)
A20: +2 weeks | B20: =IF(B$2="","",$B$2+14) -> #REF! | D20: PO | E20: PO | F20: Post-Kaizen Action Plan, Communication Plan, Training Plan Status
B21: =IF(B$2="","",$B$2+14) -> #REF! | D21: PO | E21: PO | F21: Validate performance against target state
B22: =IF(B$2="","",$B$2+14) -> #REF! | D22: PO | E22: PO, ES, F | F22: Escalate to ES and F, if red
A23: +3 weeks | B23: =IF(B$2="","",$B$2+21) -> #REF! | D23: PO | E23: PO | F23: Post-Kaizen Action Plan, Communication Plan, Training Plan Status
B24: =IF(B$2="","",$B$2+21) -> #REF! | D24: PO | E24: PO | F24: Validate performance against target state
B25: =IF(B$2="","",$B$2+21) -> #REF! | D25: PO | E25: PO, ES, F | F25: Escalate to ES and F, if red
A26: +30 days | B26: =IF(B$2="","",$B$2+30) -> #REF! | D26: PO | E26: PO | F26: Verify process performance (what's working/not working). Target state from event has been achieved.
B27: =IF(B$2="","",$B$2+30) -> #REF! | D27: PO | E27: PO, F | F27: Problem Solving cadence in place to continuously improve the process performance
B28: =IF(B$2="","",$B$2+30) -> #REF! | D28: PO | E28: PO | F28: Review Standard Work - is it being followed? If not, why?
B29: =IF(B$2="","",$B$2+30) -> #REF! | D29: PO | E29: PO, F | F29: Complete a waste walk. Are there additional ideas to for improvement?
B30: =IF(B$2="","",$B$2+30) -> #REF! | D30: PO | E30: ES, PO, F | F30: Verify leader(s) are performing their leader standard work. (Going to genba, helping the team break down barriers, and supporting the Lean Management System)
B31: =IF(B$2="","",$B$2+30) -> #REF! | D31: PO | E31: ES, PO, F | F31: Verify the visual management system is giving responsive feedback and driving changes in behavior when trending in the wrong direction.
B32: =IF(B$2="","",$B$2+30) -> #REF! | D32: PO | E32: ES, PO, F | F32: Escalate if red/help needed
A33: +60 days | B33: =IF(B$2="","",$B$2+60) -> #REF! | D33: PO | E33: PO | F33: Verify process performance (what's working/not working). Target state from event has been achieved.
B34: =IF(B$2="","",$B$2+60) -> #REF! | D34: PO | E34: PO, F | F34: Problem Solving cadence in place to continuously improve the process performance
B35: =IF(B$2="","",$B$2+60) -> #REF! | D35: PO | E35: PO | F35: Review Standard Work - is it being followed? If not, why?
B36: =IF(B$2="","",$B$2+60) -> #REF! | D36: PO | E36: PO, F | F36: Complete a waste walk. Are there additional ideas to for improvement?
B37: =IF(B$2="","",$B$2+60) -> #REF! | D37: PO | E37: ES, PO, F | F37: Verify leader(s) are performing their leader standard work. (Going to genba, helping the team break down barriers, and supporting the Lean Management System)
B38: =IF(B$2="","",$B$2+60) -> #REF! | D38: PO | E38: ES, PO, F | F38: Verify the visual management system is giving responsive feedback and driving changes in behavior when trending in the wrong direction.
B39: =IF(B$2="","",$B$2+60) -> #REF! | D39: PO | E39: ES, PO, F | F39: Escalate if red/help needed
A40: +90 days | B40: =IF(B$2="","",$B$2+90) -> #REF! | D40: PO | E40: PO | F40: Verify process performance (what's working/not working). Target state from event has been achieved.
B41: =IF(B$2="","",$B$2+90) -> #REF! | D41: PO | E41: PO, F | F41: Problem Solving cadence in place to continuously improve the process performance
...

Sheet Participant Survey
A1: Kaizen Event Participant Survey | G1: RETURN TO USER GUIDE
A2: An optional survey to be given to participants on the last day of the event and the results reviewed for continuous improvement opportunities.
B4: Event Name: | F4: Date:
A6: # | B6: Question | C6: Strongly Agree | D6: Agree | E6: Disagree | F6: Strongly Disagree | G6: Comments
A7: 1 | B7: I felt empowered to make changes to the process this week.
A8: 2 | B8: I am satisfied with the facilitator's performance in leading/coaching the event.
A9: 3 | B9: I am satisfied with the results impact of this week's efforts.
A10: 4 | B10: I am pleased with this week as a personal learning experience.
A11: 5 | B11: The training provided during the event was clear and meaningful.
A12: 6 | B12: I am interested in participating in another Kaizen event in the future.
A13: 7 | B13: I feel this event had appropriate leadership support (Executive Sponsonr & Process Owner).
A14: 8 | B14: I have a good undertanding of the Lean tools applied during this event.
A15: 9 | B15: The preparation done prior to the event was adequate and appropriate.
A16: 10 | B16: I understand why this event was done and its strategic importance to the business.
A17: Other Comments or Questions:
A19: Thank you for your Feedback!!

Sheet Key Role Survey
A1: Key Roles Survey | E1: RETURN TO USER GUIDE
A2: A guide for conducting a post-Kaizen debrief / reflection session with the Executive Sponsor, Process Owner, Facilitator and Team Leader.
A3: It is recommended to do after the final report out, ideally within 3 business days.
A5: # | B5: Question | C5: Yes | D5: No | E5: Comments
A6: 1 | B6: Was training completed and relevant to the week?
A7: 2 | B7: Were participants fully committed to the week? (i.e. people not stepping in and out)
A8: 3 | B8: Was the prep work for the event sufficient and complete?
A9: 4 | B9: Did the Executive Sponsor appropriately kickoff the event?
A10: 5 | B10: Were the daily debriefs well attended including Executive Sponsor and stakeholders?
A11: 6 | B11: Was the team trystorming by Wednesday?
A12: 7 | B12: Were solutions setup for sustainment in the week? (i.e. Standard work written, Daily Mgmt leveraged)
A13: 8 | B13: Was the final Report Out well attended including Executive Sponsor and stakeholders?
A14: 9 | B14: Does the Post-Kaizen Action Plan have less than 5 items and all due within 30 days?
A15: 10 | B15: Were leaders in the kickoff, debriefs, and the report out modeling the GE Leadership Behaviors?
A16: 11 | B16: Were the Kaizen metric targets achieved in the week?
A18: Worked Well (+) | D18: Change for Next Time (∆)

Sheet Reason Matrix
A1: Parts Delay Reasons
A2: In 2024, 79% of Planned Outages received less than 100% of parts before scheduled start. (CSA Planned Only)
A3: Reason | B3: Why? | C3: What's Been Tried | D3: New Opportunities | E3: Next Steps
A4: Unrealistic metric? Is it necessary to have 100% of parts arrive before scheduled start?
A5: Lack of visibility
A6: Supplier issues
A7: Unclear roles & responsibilities
A8: Bandwidth issue
A9: Lead time issues
A10: Too many people involved in tracking/acquiring parts
A11: Parts ordered too late
A12: Inventory re-allocated to prioritized outage
A19: Tableau Server
A20: https://tableau.cloud.digital.ge.com/#/views/xPGSCSOutagesDashboard/L1RootCauses?:iid=3

Sheet Template
A2: XXX (Project Name)
A3: Idea Approved (Stage 0): | B3: =IF(OR(ISBLANK(B7),ISBLANK(E7),ISBLANK(I13),ISBLANK(I17)),"Not Approved", "Approved") -> Not Approved
A4: Total Hours to Implement Initiative
A6: VO Owner: | B6: Jim Vono | D6: Incremental Systems Investment Required: | E6: No
A7: Approved On: | D7: Approved On:
A10: Team | C10: Average Workweek | D10: Process Step L2 | E10: Average Time (min/wk) | F10: Current FTE (As of May 2026) | G10: Total NVA Eliminated Time per Year (hrs) | H10: Functional Owner | I10: Approved On:
A11: Personna 1 | B11: Current State | C11: 60 | D11: xxxx | E11: 0 | F11: 0 | G11: =E11*52*F11 -> 0
B12: Future State | C12: 60 | D12: xxxx | E12: 0 | F12: 0 | G12: =(E12*52)/60*F12 -> 0
D13: Persona 1 Capacity Gain / NVA Eliminated | G13: =G11-G12 -> 0
A15: Personna 2 | B15: Current State | C15: 60 | D15: xxxx | E15: 0 | F15: 0 | G15: =E15*52*F15 -> 0
B16: Future State | C16: 60 | D16: xxxx | E16: 0 | F16: 0 | G16: =(E16*52)/60*F16 -> 0
D17: Persona 2 Capacity gain / NVA Eliminated | G17: =G15-G16 -> 0
A19: Personna 3 | B19: Current State | C19: 60 | D19: xxx | E19: 0 | F19: 0 | G19: =E19*52*F19 -> 0
B20: Future State | C20: 60 | D20: xxx | E20: 0 | F20: 0 | G20: =(E20*52)/60*F20 -> 0
D21: Persona 3 Capacity Gain / NVA Eliminated | G21: =G19-G20 -> 0
D23: Total | G23: =G17+G13+G21 -> 0
A25: Support details
A26: Persona 1 Activity | B26: CURRENT STATE | D26: FUTURE STATE
A28: xxx | B28: 0 | D28: 0
A29: xxx | B29: 0 | D29: 0
A30: xxx | B30: 0 | D30: 0
A31: xxx | B31: 0 | D31: 0
A32: xxx | B32: 0 | D32: 0
A33: Persona 1 Total | B33: =SUM(B28:B32) -> 0 | D33: =SUM(D28:D32) -> 0
A34: Persona 2 Activity | B34: CURRENT STATE | D34: FUTURE STATE
A36: Sub-Task 1 | D36: 0
A37: Sub-Task 2
A38: Sub-Task 3
A39: Sub-Task 4
A40: Sub-Task 5
A41: Persona 2 Total | B41: =SUM(B36:B40) -> 0 | D41: =SUM(D36:D40) -> 0
A42: Persona 3 Activity | B42: CURRENT STATE | D42: FUTURE STATE
A44: Sub-Task 1
A45: Sub-Task 2
A46: Sub-Task 3
A47: Sub-Task 4
A48: Sub-Task 5
A49: Persona 3 Total | B49: =SUM(B44:B48) -> 0 | D49: =SUM(D44:D48) -> 0
A52: WITH CUT-IN TIMING | B52: % of year benefit
A53: TOTAL 2026 benefit | D53: =G23*B53 -> 0 | E53: NVA hrs
...

Sheet PCA
A2: PCA Tool Enhancements
A3: Idea Approved (Stage 0): | B3: =IF(OR(ISBLANK(B7),ISBLANK(E7),ISBLANK(I13),ISBLANK(I17)),"Not Approved", "Approved") -> Not Approved
A4: Total Hours to Implement Initiative
A6: VO Owner: | B6: Jim Vono | D6: Incremental Systems Investment Required: | E6: Yes
A7: Approved On: | D7: Approved On:
A10: Team | C10: Average Workweek | D10: Process Step L2 | E10: Average Time (min/wk) | F10: Current FTE (As of June 2024) | G10: Total NVA Eliminated Time per Year (hrs) | H10: Functional Owner | I10: Approved On:
A11: PCA | B11: Current State | D11: OPU Preparation | E11: =B46 -> 210 | F11: 80 | G11: =((E11*52)/60)*F11 -> 14560
B12: Future State | D12: OPU consolidation tool + CDSi & PPR merge | E12: =D46 -> 85 | F12: 80 | G12: =((E12*52)/60)*F12 -> 5893.3333
D13: Persona 1 Capacity Gain / NVA Eliminated | G13: =G11-G12 -> 8666.6667
B15: Current State | D15: Primavera Schedule Baseline Optimized | E15: =B54 -> 923.07692 | F15: 80 | G15: =((E15*52)/60)*F15 -> 64000
B16: Future State | D16: Primavera Schedule Baseline Optimized (AI) | E16: 818 | F16: 80 | G16: =((E16*52)/60)*F16 -> 56714.667
D17: Persona 2 Capacity gain / NVA Eliminated | G17: =G15-G16 -> 7285.3333
B19: Current State | D19: OPU Email | E19: 95 | F19: 80 | G19: =((E19*52)/60)*F19 -> 6586.6667
B20: Future State | D20: OPU Email (AI) | E20: 40 | F20: 80 | G20: =((E20*52)/60)*F20 -> 2773.3333
D21: Persona 2 Capacity gain / NVA Eliminated | G21: =G19-G20 -> 3813.3333
B23: Current State | D23: PCA Excel Audit File Issue | E23: =B62 -> 92.31 | F23: 80 | G23: =((E23*52)/60)*F23 -> 6400.16
B24: Future State | D24: IRFPCA Audit | E24: =D62 -> 62.11 | F24: 80 | G24: =((E24*52)/60)*F24 -> 4306.2933
D25: Persona 3 Capacity Gain / NVA Eliminated | G25: =G23-G24 -> 2093.8667
B27: Current State | D27: Initial Primavera Schedule Draft Creation 7F | E27: 57.692308 | F27: 80 | G27: =((E27*52)/60)*F27 -> 4000
B28: Future State | D28: SMT for 7F (Automatized initial P6 Schedule Creation) | E28: 22 | F28: 80 | G28: =((E28*52)/60)*F28 -> 1525.3333
D29: Persona 3 Capacity Gain / NVA Eliminated | G29: =G27-G28 -> 2474.6667
B31: Current State | D31: Creation of Initial Task list for Field Time | E31: 20 | F31: 80 | G31: =((E31*52)/60)*F31 -> 1386.6667
B32: Future State | D32: Guided Time Entry Tool sync with P6 (all Regions) | E32: 5 | F32: 80 | G32: =((E32*52)/60)*F32 -> 346.66667
D33: Persona 3 Capacity Gain / NVA Eliminated | G33: =G31-G32 -> 1040
D36: Total | G36: =G17+G13+G25+G29+G33+G21 -> 25373.867
A38: Support details
A39: Persona 1 Activity | B39: CURRENT STATE | D39: FUTURE STATE
A41: Merge CDSi with PPR | B41: 60 | D41: 30
A42: Check previous week and consolidate | B42: 150 | D42: =+B42-95 -> 55
B43: 0 | D43: 0
A46: Persona 1 Total | B46: =SUM(B41:B45) -> 210 | D46: =SUM(D41:D45) -> 85
A47: Persona 2 Activity | B47: CURRENT STATE | D47: FUTURE STATE
A49: Baseline optimization (avg 20 events per year) | B49: 923.07692 | D49: 818
A54: Persona 2 Total | B54: =SUM(B49:B53) -> 923.07692 | D54: =SUM(D49:D53) -> 818
A55: Persona 3 Activity | B55: CURRENT STATE | D55: FUTURE STATE
A57: PCA Audit | B57: 92.31 | D57: =+B57-30.2 -> 62.11
A62: Persona 3 Total | B62: =SUM(B57:B61) -> 92.31 | D62: =SUM(D57:D61) -> 62.11
A65: WITH CUT-IN TIMING | B65: % of year benefit
A66: TOTAL 2026 benefit | B66: 0.5 | D66: =G36*B66 -> 12686.933 | E66: NVA hrs
A68: TOTAL 2027 benefit | B68: 0.5 | D68: =G36*B68 -> 12686.933 | E68: NVA hrs
...
